{
  "timestamp": "2025-04-06T21:35:08.093630",
  "error_type": "TypeError",
  "error_message": "ValidationError() takes no keyword arguments",
  "traceback": "Traceback (most recent call last):\n  File \"/home/andrii/Documents/Projects/Mathtermind/src/services/auth_service.py\", line 199, in register\n    raise ValidationError(\n          ~~~~~~~~~~~~~~~^\n        message=f\"Username '{username}' is already taken\",\n        ^^^^^^^^^^^^^^^^^^^^^^^^^^^^^^^^^^^^^^^^^^^^^^^^^^\n        details={\"field\": \"username\", \"value\": username}\n        ^^^^^^^^^^^^^^^^^^^^^^^^^^^^^^^^^^^^^^^^^^^^^^^^\n    )\n    ^\nTypeError: ValidationError() takes no keyword arguments\n",
  "system_info": {
    "platform": "Linux-6.12.19-1-lts-x86_64-with-glibc2.41",
    "python_version": "3.13.2",
    "hostname": "archlinux",
    "pid": 1362997,
    "cwd": "/home/andrii/Documents/Projects/Mathtermind",
    "user": "andrii",
    "executable": "/home/andrii/Documents/Projects/Mathtermind/venv/bin/python"
  },
  "additional_data": {
    "context": {
      "username": "testuser",
      "email": "test@example.com"
    }
  }
}